Workbook

Sheet INC
A1: NVDA
B2: FY | C2: FY | D2: FY | E2: FY | F2: FY | G2: FY | H2: FY | I2: FY | J2: FY | K2: FY | L2: FY | M2: FY | N2: FY
A3: Millions | B3: 2027E | C3: 2026E | D3: 2025E | E3: 2024 | F3: 2023 | G3: 2022 | H3: 2021 | I3: 2020 | J3: 2019 | K3: 2018 | L3: 2017 | M3: 2016 | N3: 2015
A4: Sales & Revenues:
A5: Revenue | B5: =C5*(1+B44) -> 472907.03 | C5: =D5*(1+C44) -> 315271.35 | D5: =E5*(1+D44) -> 137074.5 | E5: 60922 | F5: 26974 | G5: 26914 | H5: 16675 | I5: 10918 | J5: 11716 | K5: 9714 | L5: 6910 | M5: 5010 | N5: 4682
A6: Cost of revenue | B6: =B5-B7 -> 165517.46 | C6: =C5-C7 -> 94423.769 | D6: =D5-D7 -> 35639.37 | E6: 16621 | F6: 11618 | G6: 9439 | H6: 6279 | I6: 4150 | J6: 4545 | K6: 3892 | L6: 2847 | M6: 2199 | N6: 2083
A7: Gross profit | B7: =B5*B46 -> 307389.57 | C7: =C5*C46 -> 220847.58 | D7: =D5*D46 -> 101435.13 | E7: =E5-E6 -> 44301 | F7: =F5-F6 -> 15356 | G7: =G5-G6 -> 17475 | H7: =H5-H6 -> 10396 | I7: =I5-I6 -> 6768 | J7: =J5-J6 -> 7171 | K7: =K5-K6 -> 5822 | L7: =L5-L6 -> 4063 | ... N7: =N5-N6 -> 2599
A9: Operating Costs
A10: Research and development | B10: =B$5*B47 -> 99310.475 | C10: =C$5*C47 -> 61477.913 | D10: =D$5*D47 -> 13707.45 | E10: 8675 | F10: 7339 | G10: 5268 | H10: 3924 | I10: 2829 | J10: 2376 | K10: 1797 | L10: 1463 | M10: 1331 | N10: 1360
A11: Sales, general and administrative | B11: =B$5*B48 -> 43412.865 | C11: =C$5*C48 -> 28941.91 | D11: =D$5*D48 -> 3783.2562 | E11: 2654 | F11: 2440 | G11: 2166 | H11: 1940 | I11: 1093 | J11: 991 | K11: 815 | L11: 663 | M11: 602 | N11: 480
A12: Restructuring and other charges | B12: =B$5*B49 -> 0 | C12: =C$5*C49 -> 0 | D12: =D$5*D49 -> 0 | E12: 0 | F12: 0 | G12: 0 | H12: 0 | I12: 0 | J12: 0 | K12: 0 | L12: 3 | M12: 131 | N12: 0
A13: Acquisition termination cost | B13: =B$5*B50 -> 0 | C13: =C$5*C50 -> 0 | D13: =D$5*D50 -> 0 | E13: 0 | F13: 1353 | G13: 0 | H13: 0 | I13: 0 | J13: 0 | K13: 0 | L13: 0 | M13: 0 | N13: 0
A14: Total Operating Costs | B14: =SUM(B10:B13) -> 142723.34 | C14: =SUM(C10:C13) -> 90419.823 | D14: =SUM(D10:D13) -> 17490.706 | E14: =SUM(E10:E13) -> 11329 | F14: =SUM(F10:F13) -> 11132 | G14: =SUM(G10:G13) -> 7434 | H14: =SUM(H10:H13) -> 5864 | I14: =SUM(I10:I13) -> 3922 | ... N14: =SUM(N10:N13) -> 1840
A16: Operating Profit | B16: =B7-B14 -> 164666.23 | C16: =C7-C14 -> 130427.76 | D16: =D7-D14 -> 83944.424 | E16: =E7-E14 -> 32972 | F16: =F7-F14 -> 4224 | G16: =G7-G14 -> 10041 | H16: =H7-H14 -> 4532 | I16: =I7-I14 -> 2846 | ... N16: =N7-N14 -> 759
A18: Interest income | B18: =B$5*B51 -> 4256.1632 | C18: =C$5*C51 -> 1891.6281 | D18: =D$5*D51 -> 1919.043 | E18: 866 | F18: 267 | G18: 29 | H18: 57 | I18: 178 | J18: 136 | K18: 69 | L18: 54 | M18: 39 | N18: 28
A19: Interest expense | B19: =B$5*B52 -> -3641.3841 | C19: =C$5*C52 -> -2427.5894 | D19: =D$5*D52 -> -274.149 | E19: -257 | F19: -262 | G19: -236 | H19: -184 | I19: -52 | J19: -58 | K19: -61 | L19: -58 | M19: -47 | N19: -46
A20: Other, net | B20: =B$5*B53 -> -94.581405 | C20: =C$5*C53 -> 126.10854 | D20: =D$5*D53 -> 452.34585 | E20: 237 | F20: -48 | G20: 107 | H20: 4 | I20: -2 | J20: 14 | K20: -22 | L20: -25 | M20: 4 | N20: 14
A21: Other income (expense), net | B21: =SUM(B18:B20) -> 520.19773 | C21: =SUM(C18:C20) -> -409.85276 | D21: =SUM(D18:D20) -> 2097.2398 | E21: =SUM(E18:E20) -> 846 | F21: =SUM(F18:F20) -> -43 | G21: =SUM(G18:G20) -> -100 | H21: =SUM(H18:H20) -> -123 | I21: =SUM(I18:I20) -> 124 | ... N21: =SUM(N18:N20) -> -4
A23: Consolidated profit before taxes | B23: =B16+B21 -> 165186.42 | C23: =C16+C21 -> 130017.9 | D23: =D16+D21 -> 86041.664 | E23: =E16+E21 -> 33818 | F23: =F16+F21 -> 4181 | G23: =G16+G21 -> 9941 | H23: =H16+H21 -> 4409 | I23: =I16+I21 -> 2970 | ... N23: =N16+N21 -> 755
A25: Income tax expense (benefit) | B25: =B23*B73 -> 23126.099 | C25: =C23*C73 -> 19502.686 | D25: =D23*D73 -> 12476.041 | E25: 4058 | F25: -187 | G25: 189 | H25: 77 | I25: 174 | J25: -245 | K25: 149 | L25: 239 | M25: 129 | N25: 124
A26: Net income | B26: =B23-B25 -> 142060.32 | C26: =C23-C25 -> 110515.22 | D26: =D23-D25 -> 73565.622 | E26: =E23-E25 -> 29760 | F26: =F23-F25 -> 4368 | G26: =G23-G25 -> 9752 | H26: =H23-H25 -> 4332 | I26: =I23-I25 -> 2796 | ... N26: =N23-N25 -> 631
A29: EPS
A30: Profit/share-basic | B30: =B$26/B37 -> 5.8117316 | C30: =C$26/C37 -> 4.4986056 | D30: =D$26/D37 -> 2.9795716 | E30: 12.05 | F30: 1.76 | G30: 3.91 | H30: 7.02 | I30: 4.59 | J30: 6.81 | K30: 5.09 | L30: 3.08 | M30: 1.13 | N30: 1.14
A31: Profit/share-diluted | B31: =B$26/B38 -> 5.7534745 | C31: =C$26/C38 -> 4.4535113 | D31: =D$26/D38 -> 2.9497042 | E31: 11.93 | F31: 1.74 | G31: 3.85 | H31: 6.9 | I31: 4.52 | J31: 6.63 | K31: 4.82 | L31: 2.57 | M31: 1.08 | N31: 1.12
A32: Consensus | B32: 5.58 | C32: 4.44 | D32: 2.95
A36: Wtd avg shs (mill)
A37: Basic | B37: =C37*(1+B$39) -> 24443.717 | C37: =D37*(1+C$39) -> 24566.55 | D37: =E37*(D$39) -> 24690 | E37: 2469 | F37: 2487 | G37: 2496 | H37: 617 | I37: 609 | J37: 608 | K37: 599 | L37: 541 | M37: 543 | N37: 552
A38: Diluted | B38: =C38*(1+B$39) -> 24691.224 | C38: =D38*(1+C$39) -> 24815.3 | D38: =E38*(D$39) -> 24940 | E38: 2494 | F38: 2507 | G38: 2535 | H38: 628 | I38: 618 | J38: 625 | K38: 632 | L38: 649 | M38: 569 | N38: 563
A39: %change from prior year (buyback) | B39: -0.005 | C39: -0.005 | D39: 10 | E39: =E38/F38-1 -> -0.0051854807 | F39: =F38/G38-1 -> -0.011045365 | G39: =G38/H38-1 -> 3.0366242 | H39: =H38/I38-1 -> 0.01618123 | I39: =I38/J38-1 -> -0.0112 | J39: =J38/K38-1 -> -0.011075949 | K39: =K38/L38-1 -> -0.026194145 | L39: =L38/M38-1 -> 0.14059754 | M39: =M38/N38-1 -> 0.010657194
A41: DIV/share | B41: 0 | C41: 0 | D41: 0 | E41: 0 | F41: 0 | G41: 0 | H41: 0 | I41: 0 | J41: 0.61 | K41: 0.57 | L41: 0.485 | M41: 0.395 | N41: 0.34
O43: avg
A44: Revenue | B44: 0.5 | C44: 1.3 | D44: 1.25 | E44: =E5/F5-1 -> 1.2585453 | F44: =F5/G5-1 -> 0.002229323 | G44: =G5/H5-1 -> 0.61403298 | H44: =H5/I5-1 -> 0.52729438 | I44: =I5/J5-1 -> -0.068111984 | J44: =J5/K5-1 -> 0.2060943 | K44: =K5/L5-1 -> 0.40578871 | L44: =L5/M5-1 -> 0.37924152 | M44: =M5/N5-1 -> 0.070055532 | O44: =AVERAGE(E44:N44) -> 0.37724111
A45: Expenses as % of Revenue
A46: Gross Margin | B46: 0.65 | C46: 0.7005 | D46: 0.74 | E46: =E7/E5 -> 0.72717573 | F46: =F7/F5 -> 0.56928894 | G46: =G7/G5 -> 0.64929033 | H46: =H7/H5 -> 0.62344828 | I46: =I7/I5 -> 0.61989375 | J46: =J7/J5 -> 0.61206897 | K46: =K7/K5 -> 0.59934116 | L46: =L7/L5 -> 0.58798842 | ... N46: =N7/N5 -> 0.55510466 | O46: =AVERAGE(E46:N46) -> 0.61046781
A47: Research and development | B47: 0.21 | C47: 0.195 | D47: 0.1 | E47: =E10/E$5 -> 0.14239519 | F47: =F10/F$5 -> 0.27207681 | G47: =G10/G$5 -> 0.19573456 | H47: =H10/H$5 -> 0.23532234 | I47: =I10/I$5 -> 0.25911339 | J47: =J10/J$5 -> 0.20279959 | K47: =K10/K$5 -> 0.18499073 | L47: =L10/L$5 -> 0.21172214 | ... N47: =N10/N$5 -> 0.29047416 | O47: =AVERAGE(E47:N47) -> 0.22602976
A48: Sales, general and administrative | B48: 0.0918 | C48: 0.0918 | D48: 0.0276 | E48: =E11/E$5 -> 0.043563901 | F48: =F11/F$5 -> 0.090457478 | G48: =G11/G$5 -> 0.080478561 | H48: =H11/H$5 -> 0.11634183 | I48: =I11/I$5 -> 0.10010991 | J48: =J11/J$5 -> 0.084585183 | K48: =K11/K$5 -> 0.083899526 | L48: =L11/L$5 -> 0.095947902 | ... N48: =N11/N$5 -> 0.10252029 | O48: =AVERAGE(E48:N48) -> 0.091806426
A49: Restructuring and other charges | B49: 0 | C49: 0 | D49: 0 | E49: =E12/E$5 -> 0 | F49: =F12/F$5 -> 0 | G49: =G12/G$5 -> 0 | H49: =H12/H$5 -> 0 | I49: =I12/I$5 -> 0 | J49: =J12/J$5 -> 0 | K49: =K12/K$5 -> 0 | L49: =L12/L$5 -> 0.0004341534 | ... N49: =N12/N$5 -> 0 | O49: =AVERAGE(E49:N49) -> 0.0026581858
A50: Acquisition termination cost | B50: 0 | C50: 0 | D50: 0 | E50: =E13/E$5 -> 0 | F50: =F13/F$5 -> 0.050159413 | G50: =G13/G$5 -> 0 | H50: =H13/H$5 -> 0 | I50: =I13/I$5 -> 0 | J50: =J13/J$5 -> 0 | K50: =K13/K$5 -> 0 | L50: =L13/L$5 -> 0 | ... N50: =N13/N$5 -> 0 | O50: =AVERAGE(E50:N50) -> 0.0050159413
A51: Interest income | B51: 0.009 | C51: 0.006 | D51: 0.014 | E51: =E18/E$5 -> 0.014214898 | F51: =F18/F$5 -> 0.0098984207 | G51: =G18/G$5 -> 0.0010775061 | H51: =H18/H$5 -> 0.0034182909 | I51: =I18/I$5 -> 0.016303352 | J51: =J18/J$5 -> 0.011608057 | K51: =K18/K$5 -> 0.0071031501 | L51: =L18/L$5 -> 0.0078147612 | ... N51: =N18/N$5 -> 0.0059803503 | O51: =AVERAGE(E51:N51) -> 0.0085203218
A52: Interest expense | B52: -0.0077 | C52: -0.0077 | D52: -0.002 | E52: =E19/E$5 -> -0.0042185089 | F52: =F19/F$5 -> -0.009713057 | G52: =G19/G$5 -> -0.0087686706 | H52: =H19/H$5 -> -0.011034483 | I52: =I19/I$5 -> -0.0047627771 | J52: =J19/J$5 -> -0.004950495 | K52: =K19/K$5 -> -0.0062795965 | L52: =L19/L$5 -> -0.0083936324 | ... N52: =N19/N$5 -> -0.0098248612 | O52: =AVERAGE(E52:N52) -> -0.0077327319
...

Sheet CashFlow
A1: NVDA
B2: FY | C2: FY | D2: FY | E2: FY | F2: FY | G2: FY | H2: FY | I2: FY | J2: FY | K2: FY | L2: FY | M2: FY | N2: FY | O2: FY
A3: Millions | B3: 2027E | C3: 2026E | D3: 2025E | E3: 2024 | F3: 2023 | G3: 2022 | H3: 2021 | I3: 2020 | J3: 2019 | K3: 2018 | L3: 2017 | M3: 2016 | N3: 2015 | O3: 2014
A4: Cash flows from operating activities:
A5: Net income | E5: 29760 | F5: 4368 | G5: 9752 | H5: 4332 | I5: 2796 | J5: 4141 | K5: 3047 | L5: 1666 | M5: 614 | N5: 631 | O5: 440
A6: Adjustments to reconcile net income to net cash provided by operating activities:
A7: Stock-based compensation expense | E7: 3549 | F7: 2709 | G7: 2004 | H7: 1397 | I7: 844 | J7: 557 | K7: 391 | L7: 247
A8: Depreciation and amortization | E8: 1508 | F8: 1544 | G8: 1174 | H8: 1098 | I8: 381 | J8: 262 | K8: 199 | L8: 187 | M8: 197 | N8: 220 | O8: 239
A9: Deferred income taxes | E9: -2489 | F9: -2164 | G9: -406 | H9: -282 | I9: 18 | J9: -315 | K9: -359 | L9: 197
A10: (Gains) losses on investments in non-affiliated entities, net | E10: -238 | F10: 45 | G10: -100 | K10: 19 | L10: 21
A11: Acquisition termination cost | E11: 0 | F11: 1353 | G11: 0
A12: Other | E12: -278 | F12: -7 | G12: 47 | H12: -20 | I12: 5 | J12: -45 | K12: 20 | L12: 33
A13: Changes in operating assets and liabilities, net of acquisitions:
A14: Accounts receivable | E14: -6172 | F14: 822 | G14: -2215 | H14: -550 | I14: -233 | J14: -149 | K14: -440 | L14: -321
A15: Inventories | E15: -98 | F15: -2554 | G15: -774 | H15: -524 | I15: 597 | J15: -776 | K15: 0 | L15: -375
A16: Prepaid expenses and other assets | E16: -1522 | F16: -1517 | G16: -1715 | H16: -394 | I16: 77 | J16: -55 | K16: 21 | L16: -18
A17: Accounts payable | E17: 1531 | F17: -551 | G17: 568 | H17: 363 | I17: 194 | J17: -135 | K17: 90 | L17: 184
A18: Accrued and other current liabilities | E18: 2025 | F18: 1341 | G18: 581 | H18: 239 | I18: 54 | J18: 256 | K18: 33 | L18: -135
A19: Other long-term liabilities | E19: 514 | F19: 252 | G19: 192 | H19: 163 | I19: 28 | J19: 2 | K19: 481 | L19: -14
A20: Net cash provided by operating activities | E20: 28090 | F20: 5641 | G20: 9108 | H20: 5822 | I20: 4761 | J20: 3743 | K20: 3502 | L20: 1672 | M20: 1175 | N20: 906 | O20: 835
A21: Cash flows from investing activities:
A22: Proceeds from maturities of marketable securities | E22: 9732 | F22: 19425 | G22: 15197 | H22: 8792 | I22: 4744 | J22: 7232 | K22: 1078 | L22: 969
A23: Proceeds from sales of marketable securities | E23: 50 | F23: 1806 | G23: 1023 | H23: 527 | I23: 3365 | J23: 428 | K23: 863 | L23: 1546
A24: Purchases of marketable securities | E24: -18211 | F24: -11897 | G24: -24787 | H24: -19308 | I24: -1461 | J24: -11148 | K24: -36 | L24: -3134
A25: Purchases related to property and equipment and intangible assets | E25: -1069 | F25: -1833 | G25: -976 | H25: -1128 | I25: -489 | J25: -600 | K25: -593 | L25: -176 | M25: -86 | N25: -122 | O25: -255
A26: Acquisitions, net of cash acquired | E26: -83 | F26: -49 | G26: -263 | H26: -8524 | I26: -4 | J26: 0 | K26: 0 | L26: 0
A27: Investments in non-affiliated entities and other, net | E27: -985 | F27: -77 | G27: -24 | H27: -34 | I27: -10 | J27: -9 | K27: -36 | L27: -5
A28: Net cash provided by (used in) investing activities | E28: -10566 | F28: 7375 | G28: -9830 | H28: -19675 | I28: 6145 | J28: -4097 | K28: 1278 | L28: -793
A29: Cash flows from financing activities:
A30: Proceeds from issuance of debt | J30: 0 | K30: 0 | L30: 1988
A31: Proceeds related to employee stock plans | E31: 403 | F31: 355 | G31: 281 | H31: 4968 | I31: 0 | J31: 137 | K31: 139 | L31: 167
A32: Payments related to repurchases of common stock | E32: -9533 | F32: -10039 | G32: 0 | H32: 194 | I32: 149
A33: Payments related to tax on restricted stock units | E33: -2783 | F33: -1475 | G33: -1904 | H33: -942 | I33: -551 | J33: -1032 | K33: -612 | L33: -176
A34: Repayment of debt | E34: -1250 | F34: 0 | G34: -1000 | H34: -395 | I34: -390 | J34: -16 | K34: -812 | L34: -673
A35: Dividends paid | E35: -395 | F35: -398 | G35: -399 | H35: -17 | I35: 0 | J35: -371 | K35: -341 | L35: -261
A36: Principal payments on property and equipment and intangible assets | E36: -74 | F36: -58 | G36: -83 | H36: 0 | I36: 0 | J36: 0 | K36: 0 | L36: 0
A37: Issuance of debt, net of issuance costs | E37: 0 | F37: 0 | G37: 4977 | H37: 0 | I37: 0 | J37: 0 | K37: 0 | L37: 0
A38: Other | E38: -1 | F38: -2 | G38: -7 | H38: -4 | I38: 0 | J38: -5 | K38: -9 | L38: -15
A39: Net cash provided by (used in) financing activities | E39: -13633 | F39: -11617 | G39: 1865 | H39: 3804 | I39: -792 | J39: -2866 | K39: -2544 | L39: 291
A40: Change in cash and cash equivalents | E40: 3891 | F40: 1399 | G40: 1143 | H40: -10049 | I40: 10114 | J40: -3220 | K40: 2236 | L40: 1170
...

Sheet WACC
A1: Debt: | B1: 8459
A2: Cost of Debt: | B2: 0.0266
A3: Equity: | B3: 3430448
A4: Beta: | B4: 1.62
A5: rf: | B5: 0.0453
A6: Equity Risk Premium: | B6: =9.5%-B5 -> 0.0497
A7: CAPM Cost of Capital: | B7: =B5+(B4*B6) -> 0.125814
A8: Tax Rate: | B8: 0.145
A10: WACC: | B10: =((B3/(B3+B1))*B7)+((B1/(B3+B1))*B2*(1-B8)) -> 0.12556047

Sheet DCF
A1: Nvidia (NVDA)
F2: Current P/E | G2: 54.88
A3: Analyst: Jacob Geiger | F3: Terminal Discount Rate = | G3: 0.12 | H3: WACC = | I3: 0.12556047
A4: Date: 2/22/2025 | F4: Terminal FCF Growth = | G4: 0.1025
F5: Implied P/E= | G5: 63
A7: Year | B7: 2025E | C7: 2026E | D7: 2027E | E7: 2028E | F7: 2029E | G7: 2030E | H7: 2031E | I7: 2032E | J7: 2033E | K7: 2034E | L7: 2035E
A9: Revenue | B9: =INC!D5 -> 137074.5 | C9: =INC!C5 -> 315271.35 | D9: =INC!B5 -> 472907.03 | E9: =(D9*(1+E10)) -> 520197.73 | F9: =(E9*(1+F10)) -> 572217.5 | G9: =(F9*(1+G10)) -> 629439.25 | H9: =(G9*(1+H10)) -> 692383.18 | I9: =(H9*(1+I10)) -> 761621.49 | J9: =(I9*(1+J10)) -> 837783.64 | K9: =(J9*(1+K10)) -> 921562.01 | L9: =(K9*(1+L10)) -> 1013718.2
A10: % Growth | C10: =(C9/B9)-1 -> 1.3 | D10: =(D9/C9)-1 -> 0.5 | E10: 0.1 | F10: 0.1 | G10: 0.1 | H10: 0.1 | I10: 0.1 | J10: 0.1 | K10: 0.1 | L10: 0.1
A12: Operating Profit | B12: =INC!D16 -> 83944.424 | C12: =INC!C16 -> 130427.76 | D12: =INC!B16 -> 164666.23 | E12: =(E9*E13) -> 148256.35 | F12: =(F9*F13) -> 163081.99 | G12: =(G9*G13) -> 179390.19 | H12: =(H9*H13) -> 197329.2 | I12: =(I9*I13) -> 217062.13 | J12: =(J9*J13) -> 238768.34 | K12: =(K9*K13) -> 262645.17 | L12: =(L9*L13) -> 288909.69
A13: Operating Margin | B13: =B12/B9 -> 0.6124 | C13: =C12/C9 -> 0.4137 | D13: =D12/D9 -> 0.3482 | E13: 0.285 | F13: =E13 -> 0.285 | G13: =F13 -> 0.285 | H13: =G13 -> 0.285 | I13: =H13 -> 0.285 | J13: =I13 -> 0.285 | K13: =J13 -> 0.285 | L13: =K13 -> 0.285
A15: Interest and Other | B15: =INC!D21 -> 2097.2398 | C15: =INC!C21 -> -409.85276 | D15: =INC!B21 -> 520.19773 | E15: =E16*E9 -> 572.2175 | F15: =F16*F9 -> 629.43925 | G15: =G16*G9 -> 692.38318 | H15: =H16*H9 -> 761.62149 | I15: =I16*I9 -> 837.78364 | J15: =J16*J9 -> 921.56201 | K15: =K16*K9 -> 1013.7182 | L15: =L16*L9 -> 1115.09
A16: Interest % of Sales | B16: =B15/B9 -> 0.0153 | C16: =C15/C9 -> -0.0013 | D16: =D15/D9 -> 0.0011 | E16: =D16 -> 0.0011 | F16: =E16 -> 0.0011 | G16: =F16 -> 0.0011 | H16: =G16 -> 0.0011 | I16: =H16 -> 0.0011 | J16: =I16 -> 0.0011 | K16: =J16 -> 0.0011 | L16: =K16 -> 0.0011
A18: Income Before Taxes | B18: =INC!D23 -> 86041.664 | C18: =INC!C23 -> 130017.9 | D18: =INC!B23 -> 165186.42 | E18: =E12-E15 -> 147684.13 | F18: =F12-F15 -> 162452.55 | G18: =G12-G15 -> 178697.8 | H18: =H12-H15 -> 196567.58 | I18: =I12-I15 -> 216224.34 | J18: =J12-J15 -> 237846.78 | K18: =K12-K15 -> 261631.45 | L18: =L12-L15 -> 287794.6
A20: Taxes | B20: =INC!D25 -> 12476.041 | C20: =INC!C25 -> 19502.686 | D20: =INC!B25 -> 23126.099 | E20: =(E12+E15)*E21 -> 20836 | F20: =(F12+F15)*F21 -> 22919.6 | G20: =(G12+G15)*G21 -> 25211.56 | H20: =(H12+H15)*H21 -> 27732.716 | I20: =(I12+I15)*I21 -> 30505.987 | J20: =(J12+J15)*J21 -> 33556.586 | K20: =(K12+K15)*K21 -> 36912.245 | L20: =(L12+L15)*L21 -> 40603.469
A21: Tax Rate | B21: =INC!D73 -> 0.145 | C21: =INC!C73 -> 0.15 | D21: =INC!B73 -> 0.14 | E21: =D21 -> 0.14 | F21: =E21 -> 0.14 | G21: =F21 -> 0.14 | H21: =G21 -> 0.14 | I21: =H21 -> 0.14 | J21: =I21 -> 0.14 | K21: =J21 -> 0.14 | L21: =K21 -> 0.14
A23: Net Income | B23: =INC!D26 -> 73565.622 | C23: =INC!C26 -> 110515.22 | D23: =INC!B26 -> 142060.32 | E23: =E18-E20 -> 126848.14 | F23: =F18-F20 -> 139532.95 | G23: =G18-G20 -> 153486.24 | H23: =H18-H20 -> 168834.87 | I23: =I18-I20 -> 185718.35 | J23: =J18-J20 -> 204290.19 | K23: =K18-K20 -> 224719.21 | L23: =L18-L20 -> 247191.13
A24: % Growth | C24: =+(C23/B23)-1 -> 0.50226716 | D24: =+(D23/C23)-1 -> 0.28543675 | E24: =+(E23/D23)-1 -> -0.1070826 | F24: =+(F23/E23)-1 -> 0.1 | G24: =+(G23/F23)-1 -> 0.1 | H24: =+(H23/G23)-1 -> 0.1 | I24: =+(I23/H23)-1 -> 0.1 | J24: =+(J23/I23)-1 -> 0.1 | ... L24: =+(L23/K23)-1 -> 0.1
A26: Add Depreciation/Amort | B26: =INC!D75 -> 5249.9533 | C26: =INC!C75 -> 12074.893 | D26: =INC!B75 -> 18112.339 | E26: =E9*E27 -> 19923.573 | F26: =F9*F27 -> 21915.93 | G26: =G9*G27 -> 24107.523 | H26: =H9*H27 -> 26518.276 | I26: =I9*I27 -> 29170.103 | J26: =J9*J27 -> 32087.113 | K26: =K9*K27 -> 35295.825 | L26: =L9*L27 -> 38825.407
A27: % of Sales | B27: =B26/B9 -> 0.0383 | C27: =C26/C9 -> 0.0383 | D27: =D26/D9 -> 0.0383 | E27: =D27 -> 0.0383 | F27: =E27 -> 0.0383 | G27: =F27 -> 0.0383 | H27: =G27 -> 0.0383 | I27: =H27 -> 0.0383 | J27: =I27 -> 0.0383 | K27: =J27 -> 0.0383 | L27: =K27 -> 0.0383
A28: Plus/(minus) Changes WC | B28: =INC!D87 -> -12776.782 | C28: =INC!C87 -> -32966.417 | D28: =INC!B87 -> -29162.6 | E28: =E29*E9 -> -32078.86 | F28: =F29*F9 -> -35286.746 | G28: =G29*G9 -> -38815.42 | H28: =H29*H9 -> -42696.962 | I28: =I29*I9 -> -46966.659 | J28: =J29*J9 -> -51663.325 | K28: =K29*K9 -> -56829.657 | L28: =L29*L9 -> -62512.623
A29: % of Sales | B29: =B28/B9 -> -0.093210499 | C29: =C28/C9 -> -0.10456522 | D29: =D28/D9 -> -0.061666667 | E29: =D29 -> -0.061666667 | F29: =E29 -> -0.061666667 | G29: =F29 -> -0.061666667 | H29: =G29 -> -0.061666667 | I29: =H29 -> -0.061666667 | J29: =I29 -> -0.061666667 | K29: =J29 -> -0.061666667 | L29: =K29 -> -0.061666667
A30: Cap Ex | B30: =INC!D78 -> -5620.0545 | C30: =INC!C78 -> -12610.854 | D30: =INC!B78 -> -18443.374 | E30: =E31*E9 -> -20287.711 | F30: =F31*F9 -> -22316.483 | G30: =G31*G9 -> -24548.131 | H30: =H31*H9 -> -27002.944 | I30: =I31*I9 -> -29703.238 | J30: =J31*J9 -> -32673.562 | K30: =K31*K9 -> -35940.918 | L30: =L31*L9 -> -39535.01
A31: Capex % of sales | B31: =B30/B9 -> -0.041 | C31: =C30/C9 -> -0.04 | D31: =D30/D9 -> -0.039 | E31: =D31 -> -0.039 | F31: =E31 -> -0.039 | G31: =F31 -> -0.039 | H31: =G31 -> -0.039 | I31: =H31 -> -0.039 | J31: =I31 -> -0.039 | K31: =J31 -> -0.039 | L31: =K31 -> -0.039
A33: Free Cash Flow | B33: =+B23+B26+B30+B28 -> 60418.739 | C33: =+C23+C26+C30+C28 -> 77012.84 | D33: =+D23+D26+D30+D28 -> 112566.69 | E33: =+E23+E26+E30+E28 -> 94405.137 | F33: =+F23+F26+F30+F28 -> 103845.65 | G33: =+G23+G26+G30+G28 -> 114230.22 | H33: =+H23+H26+H30+H28 -> 125653.24 | I33: =+I23+I26+I30+I28 -> 138218.56 | ... L33: =+L23+L26+L30+L28 -> 183968.9
A34: % Growth | C34: =+(C33/B33)-1 -> 0.27465157 | D34: =+(D33/C33)-1 -> 0.46166132 | E34: =+(E33/D33)-1 -> -0.16134038 | F34: =+(F33/E33)-1 -> 0.1 | G34: =+(G33/F33)-1 -> 0.1 | H34: =+(H33/G33)-1 -> 0.1 | I34: =+(I33/H33)-1 -> 0.1 | J34: =+(J33/I33)-1 -> 0.1 | ... L34: =+(L33/K33)-1 -> 0.1
A36: NPV of Cash Flows | B36: {=+NPV(G3,C33:L33)} -> 663640.3 | C36: =($B$36/$B$38) -> 0.15098782
A37: NPV of terminal value | B37: =L37/(1+G3)^10 -> 3731683 | C37: =($B$37/$B$38) -> 0.84901218 | K37: Terminal Value | L37: =+(L33*(1+G4))/(G3-G4) -> 11590041
A38: Projected Equity Value | B38: =(+B36+B37) -> 4395323.3 | C38: =C36+C37 -> 1
A39: Free Cash Flow Yield | B39: =B33/(B46*B48) -> 0.018021005 | K39: Free Cash Yield | L39: =L33/L37 -> 0.015873016
A41: Current P/E | B41: =($B$46*$B$48)/B$23 -> 45.574061 | C41: =($B46*$B48)/C23 -> 30.336855 | D41: =($B46*$B48)/D23 -> 23.600426 | K41: Terminal P/E | L41: =L37/L23 -> 46.886961
A42: Projected P/E | B42: =($B$46*$B$49)/B$23 -> 59.746974 | C42: =($B$46*$B$49)/C$23 -> 39.771204 | D42: =($B$46*$B$49)/D$23 -> 30.939837
A43: Current EV/EBITDA | B43: =(($B$46*$B$48)+$B$52-$B$53)/(B$12+B$26) -> 37.252171 | C43: =(($B$46*$B$48)+$B$52-$B$53)/(C$12+C$26) -> 23.316648 | D43: =(($B$46*$B$48)+$B$52-$B$53)/(D$12+D$26) -> 18.178741 | K43: Terminal EV/EBITDA | L43: =(L37+B52-B53)/(L12+L26) -> 35.272515
A44: Projected EV/EBITDA | B44: =(($B$46*$B$49)+$B$52-$B$53)/(B$12+B$26) -> 48.941687 | C44: =(($B$46*$B$49)+$B$52-$B$53)/(C$12+C$26) -> 30.633278 | D44: =(($B$46*$B$49)+$B$52-$B$53)/(D$12+D$26) -> 23.883125
A46: Shares Outstanding | B46: =INC!D38 -> 24940
A48: Current Price | B48: 134.43
A49: Implied equity value/share | B49: =+B38/B46 -> 176.2359
A50: Upside/(Downside) to DCF | B50: =(B49-B48)/B48 -> 0.31098637
A52: Debt | B52: 8500
A53: Cash | B53: 38500
A54: Cash/share | B54: =B53/B46 -> 1.5437049

Sheet PE
A1: Ratio Comparison:
A2: NAME | B2: Ticker | C2: P/E | D2: P/S | E2: P/B | F2: P/CF | G2: EV/EBITDA TTM | H2: MKT CAP
A3: AVERAGE | C3: =AVERAGE(C4:C10) -> 74.975714 | D3: =AVERAGE(D4:D10) -> 10.451429 | E3: =AVERAGE(E4:E10) -> 12.462857 | F3: =AVERAGE(F4:F10) -> 41.373333 | G3: =AVERAGE(G4:G10) -> 41.79
A4: NVIDIA Corporation | B4: NVDA | C4: 54.82 | D4: 30.48 | E4: 51.6 | F4: 61.27 | G4: 45.04 | H4: 3.412T
A5: AMD | B5: AMD | C5: 114.28 | D5: 7.18 | E5: 3.18 | F5: 77.74 | G5: 34.3 | H5: 180.36B
A6: Intel Corporation | B6: INTC | C6: 88.08 | D6: 1.9 | E6: 1.03 | F6: - | G6: 108.18 | H6: 118.599B
A7: Qualcomm | B7: QCOM | C7: 18.73 | D7: 4.78 | E7: 7.09 | F7: 15.39 | G7: 14.24 | H7: 192.046B
A8: Broadcom Inc. | B8: AVGO | C8: 178.54 | D8: 21.59 | E8: 16.14 | F8: 55.66 | G8: 48.18 | H8: 1.071T
A9: Cisco Systems, Inc. | B9: CSCO | C9: 28.33 | D9: 4.82 | E9: 5.67 | F9: 20.31 | G9: 18.65 | H9: 257.246B
A10: Juniper Networks, Inc. | B10: JNPR | C10: 42.05 | D10: 2.41 | E10: 2.53 | F10: 17.87 | G10: 23.94 | H10: 11.972B
A12: Valuation By Multiples
A13: Current stock price: | B13: 134.43
A14: ABSOLUTE VALUATION | B14: CURRENT | C14: TARGET MULTIPLE | D14: TARGET/CURRENT | E14: TARGET PRICE
B15: Multiple | D15: Current (% of Current)
A16: P/E | B16: 54.82 | C16: 74.98 | D16: =C16/B16 -> 1.367749 | E16: =$B$13*D16 -> 183.8665
A17: P/B | B17: 51.6 | C17: 51.6 | D17: =C17/B17 -> 1 | E17: =$B$13*D17 -> 134.43
A18: P/S | B18: 30.48 | C18: 41 | D18: =C18/B18 -> 1.3451444 | E18: =$B$13*D18 -> 180.82776
A19: P/CF | B19: 61.27 | C19: 55 | D19: =C19/B19 -> 0.89766607 | E19: =$B$13*D19 -> 120.67325
D20: Average | E20: =AVERAGE(E15:E19) -> 154.94938
A25: DCF Sensitivity Analysis | B25: Discount Rate | C25: Term Growth Rate | D25: Implied P/E | E25: Target Value | F25: Upside/Downside %
A26: 12.00% Discount | B26: 0.12 | C26: 0.1025 | D26: 63 | E26: 176.2359 | F26: =E26/B$13-1 -> 0.31098637
B27: 0.12 | C27: 0.105 | D27: 73.7 | E27: 201.56947 | F27: =E27/B$13-1 -> 0.49943817
A28: 12.25% Discount | B28: 0.1225 | C28: 0.1025 | D28: 55.1 | E28: 154.33666 | F28: =E28/B$13-1 -> 0.14808198
B29: 0.1225 | C29: 0.105 | D29: 63.1 | E29: 172.95937 | F29: =E29/B$13-1 -> 0.28661286
A30: 31.00% Growth | B30: 0.3325 | C30: 0.31 | D30: 58.2 | E30: 150.19331 | F30: =E30/B$13-1 -> 0.11726036
B31: 0.33 | C31: 0.31 | D31: 65.5 | E31: 168.98688 | F31: =E31/B$13-1 -> 0.25706225
B32: 0.3275 | C32: 0.31 | D32: 74.9 | E32: 193.15008 | F32: =E32/B$13-1 -> 0.43680782
D33: Average | E33: =AVERAGE(E26:E32) -> 173.91881 | F33: =(E33-B13)/B13 -> 0.29374997
A36: Market P/E:
A37: ABSOLUTE BASIS | B37: HIGH | C37: LOW | D37: MEDIAN | E37: CURRENT | F37: TARGET RATIO | G37: IMPLIED ADJ
A38: P/E | B38: 38.23 | C38: 17.68 | D38: 23.6 | E38: 30.53 | F38: 23.6 | G38: =(F38/E38)-1 -> -0.22698985
A39: P/B | B39: 4.93 | C39: 2.45 | D39: 3.6 | E39: 5.15 | F39: 3.6 | G39: =(F39/E39)-1 -> -0.30097087
A40: P/S | B40: 3.186 | C40: 1.629 | D40: 2.32 | E40: 3.186 | F40: 2.32 | G40: =(F40/E40)-1 -> -0.27181419
A44: ANALYSIS FINAL TARGET PRICE | B44: =E33 -> 173.91881
A45: MKT P/E TARGET RATIO | B45: =F38/E38 -> 0.77301015
A46: MKT ADJ. TARGET PRICE | B46: =B44*B45 -> 134.44101
A47: MKT ADJ. UPSIDE/DOWNSIDE | B47: =B46/B13-1 -> 8.1865445e-05
A49: MKT ADJ. WEIGHT | B49: 0.77
A50: FINAL TARGET PRICE: | B50: =(B44*(1-B49))+(B46*B49) -> 143.5209
A51: FINAL UPSIDE/DOWNSIDE: | B51: =B50/B13-1 -> 0.06762553
...

Sheet GPU MARKET
A1: Company | B1: Q3 FY2023 Revenue (USD Bn) | C1: Q3 FY2024 Revenue (USD Bn) | D1: Q3 FY2023 Revenue (%) | E1: Q3 FY2024 Revenue (%)
A2: NVIDIA | B2: 14.645 | C2: 31.034 | D2: 0.82511691 | E2: 0.85992962
A3: AMD | B3: 3.104 | C3: 5.055 | D3: 0.17488309 | E3: 0.14007038
